/etc/shinit_v2: line 3: sed: command not found
/etc/shinit_v2: line 8: hostname: command not found
/etc/shinit_v2: line 42: dpkg: command not found
/uge_mnt/var/spool/uge/dl-gtb01/job_scripts/7996772: line 8: bash: command not found
/uge_mnt/home/dinesh/SENG/Pytorch/cifar10/nsgd.py:43: UserWarning: torch.matrix_rank is deprecated in favor of torch.linalg.matrix_rankand will be removed in a future PyTorch release. The parameter 'symmetric' was renamed in torch.linalg.matrix_rank to 'hermitian'. (Triggered internally at  /opt/conda/conda-bld/pytorch_1639180487213/work/aten/src/ATen/native/LinearAlgebra.cpp:473.)
  rnk = torch.matrix_rank(M)
Traceback (most recent call last):
  File "/uge_mnt/home/dinesh/SENG/Pytorch/cifar10/main_nsgd.py", line 362, in <module>
    main()
  File "/uge_mnt/home/dinesh/SENG/Pytorch/cifar10/main_nsgd.py", line 134, in main
    main_worker(args.gpu, ngpus_per_node, args)
  File "/uge_mnt/home/dinesh/SENG/Pytorch/cifar10/main_nsgd.py", line 347, in main_worker
    test_loss, test_acc = validate(epoch)
  File "/uge_mnt/home/dinesh/SENG/Pytorch/cifar10/main_nsgd.py", line 325, in validate
    for batch_idx, (inputs, targets) in enumerate(testloader):
  File "/uge_mnt/home/dinesh/anaconda3/lib/python3.9/site-packages/torch/utils/data/dataloader.py", line 521, in __next__
    data = self._next_data()
  File "/uge_mnt/home/dinesh/anaconda3/lib/python3.9/site-packages/torch/utils/data/dataloader.py", line 1203, in _next_data
    return self._process_data(data)
  File "/uge_mnt/home/dinesh/anaconda3/lib/python3.9/site-packages/torch/utils/data/dataloader.py", line 1229, in _process_data
    data.reraise()
  File "/uge_mnt/home/dinesh/anaconda3/lib/python3.9/site-packages/torch/_utils.py", line 434, in reraise
    raise exception
RuntimeError: Caught RuntimeError in DataLoader worker process 0.
Original Traceback (most recent call last):
  File "/uge_mnt/home/dinesh/anaconda3/lib/python3.9/site-packages/torch/utils/data/_utils/worker.py", line 287, in _worker_loop
    data = fetcher.fetch(index)
  File "/uge_mnt/home/dinesh/anaconda3/lib/python3.9/site-packages/torch/utils/data/_utils/fetch.py", line 49, in fetch
    data = [self.dataset[idx] for idx in possibly_batched_index]
  File "/uge_mnt/home/dinesh/anaconda3/lib/python3.9/site-packages/torch/utils/data/_utils/fetch.py", line 49, in <listcomp>
    data = [self.dataset[idx] for idx in possibly_batched_index]
  File "/uge_mnt/home/dinesh/anaconda3/lib/python3.9/site-packages/torchvision/datasets/mnist.py", line 134, in __getitem__
    img = self.transform(img)
  File "/uge_mnt/home/dinesh/anaconda3/lib/python3.9/site-packages/torchvision/transforms/transforms.py", line 61, in __call__
    img = t(img)
  File "/uge_mnt/home/dinesh/anaconda3/lib/python3.9/site-packages/torch/nn/modules/module.py", line 1102, in _call_impl
    return forward_call(*input, **kwargs)
  File "/uge_mnt/home/dinesh/anaconda3/lib/python3.9/site-packages/torchvision/transforms/transforms.py", line 226, in forward
    return F.normalize(tensor, self.mean, self.std, self.inplace)
  File "/uge_mnt/home/dinesh/anaconda3/lib/python3.9/site-packages/torchvision/transforms/functional.py", line 351, in normalize
    tensor.sub_(mean).div_(std)
RuntimeError: output with shape [1, 28, 28] doesn't match the broadcast shape [3, 28, 28]

